Workbook

Sheet Summary
A1: E-commerce Customer Analytics – Summary
A2: Synthetic dataset built to reconcile with the presentation. All values below are live formulas over the Customer / Transaction sheets.
A3: Snapshot date (for Recency) | B3: 46266
A5: Metric | B5: Dataset | C5: PPT Target | D5: Match
A6: Total customers | B6: =COUNTA(Customer!$A$2:$A$2501) -> 2500 | C6: 2500 | D6: =IF(B6=C6,"✓","✗") -> ✓
A7: Total orders | B7: =COUNTA(Transaction!$A$2:$A$8421) -> 8420 | C7: 8420 | D7: =IF(B7=C7,"✓","✗") -> ✓
A8: Total revenue (₹) | B8: =SUM(Transaction!$H$2:$H$8421) -> 18608200 | C8: 18600000 | D8: =IF(ROUND(B8/1000000,1)=ROUND(C8/1000000,1),"✓","✗") -> ✓
A9: Average order value (₹) | B9: =B8/B7 -> 2210 | C9: 2210 | D9: =IF(ROUND(B9,0)=C9,"✓","✗") -> ✓
A10: Repeat customer rate | B10: =COUNTIF(Customer!$N$2:$N$2501,"Yes")/B6 -> 0.418 | C10: 0.418 | D10: =IF(ROUND(B10,3)=C10,"✓","✗") -> ✓
A12: Revenue by Category
A13: Category | B13: Revenue (₹) | C13: Share of Revenue | D13: Orders | E13: AOV (₹) | F13: PPT Target (₹M) | G13: Match (₹M, 1 dp)
A14: Electronics | B14: =SUMIF(Transaction!$E$2:$E$8421,A14,Transaction!$H$2:$H$8421) -> 5104200 | C14: =B14/$B$19 -> 0.27429843 | D14: =COUNTIF(Transaction!$E$2:$E$8421,A14) -> 1000 | E14: =B14/D14 -> 5104.2 | F14: 5.1 | G14: =IF(ROUND(B14/1000000,1)=F14,"✓","✗") -> ✓
A15: Home | B15: =SUMIF(Transaction!$E$2:$E$8421,A15,Transaction!$H$2:$H$8421) -> 4203100 | C15: =B15/$B$19 -> 0.22587354 | D15: =COUNTIF(Transaction!$E$2:$E$8421,A15) -> 1600 | E15: =B15/D15 -> 2626.9375 | F15: 4.2 | G15: =IF(ROUND(B15/1000000,1)=F15,"✓","✗") -> ✓
A16: Fashion | B16: =SUMIF(Transaction!$E$2:$E$8421,A16,Transaction!$H$2:$H$8421) -> 3801900 | C16: =B16/$B$19 -> 0.20431315 | D16: =COUNTIF(Transaction!$E$2:$E$8421,A16) -> 2100 | E16: =B16/D16 -> 1810.4286 | F16: 3.8 | G16: =IF(ROUND(B16/1000000,1)=F16,"✓","✗") -> ✓
A17: Grocery | B17: =SUMIF(Transaction!$E$2:$E$8421,A17,Transaction!$H$2:$H$8421) -> 3098300 | C17: =B17/$B$19 -> 0.16650186 | D17: =COUNTIF(Transaction!$E$2:$E$8421,A17) -> 2300 | E17: =B17/D17 -> 1347.087 | F17: 3.1 | G17: =IF(ROUND(B17/1000000,1)=F17,"✓","✗") -> ✓
A18: Beauty | B18: =SUMIF(Transaction!$E$2:$E$8421,A18,Transaction!$H$2:$H$8421) -> 2400700 | C18: =B18/$B$19 -> 0.12901302 | D18: =COUNTIF(Transaction!$E$2:$E$8421,A18) -> 1420 | E18: =B18/D18 -> 1690.6338 | F18: 2.4 | G18: =IF(ROUND(B18/1000000,1)=F18,"✓","✗") -> ✓
A19: Total | B19: =SUM(B14:B18) -> 18608200 | C19: =SUM(C14:C18) -> 1 | D19: =SUM(D14:D18) -> 8420 | E19: =B19/D19 -> 2210 | F19: =SUM(F14:F18) -> 18.6
A21: Monthly Revenue Trend (Jan – Aug 2026)
A22: Month | B22: Month Start | C22: Revenue (₹) | D22: Orders | E22: MoM Growth
A23: Jan 2026 | B23: 46023 | C23: =SUMIFS(Transaction!$H$2:$H$8421,Transaction!$C$2:$C$8421,">="&B23,Transaction!$C$2:$C$8421,"<"&EDATE(B23,1)) -> 1700752 | D23: =COUNTIFS(Transaction!$C$2:$C$8421,">="&B23,Transaction!$C$2:$C$8421,"<"&EDATE(B23,1)) -> 846
A24: Feb 2026 | B24: 46054 | C24: =SUMIFS(Transaction!$H$2:$H$8421,Transaction!$C$2:$C$8421,">="&B24,Transaction!$C$2:$C$8421,"<"&EDATE(B24,1)) -> 1850748 | D24: =COUNTIFS(Transaction!$C$2:$C$8421,">="&B24,Transaction!$C$2:$C$8421,"<"&EDATE(B24,1)) -> 787 | E24: =C24/C23-1 -> 0.088193928
A25: Mar 2026 | B25: 46082 | C25: =SUMIFS(Transaction!$H$2:$H$8421,Transaction!$C$2:$C$8421,">="&B25,Transaction!$C$2:$C$8421,"<"&EDATE(B25,1)) -> 2047526 | D25: =COUNTIFS(Transaction!$C$2:$C$8421,">="&B25,Transaction!$C$2:$C$8421,"<"&EDATE(B25,1)) -> 904 | E25: =C25/C24-1 -> 0.1063235
A26: Apr 2026 | B26: 46113 | C26: =SUMIFS(Transaction!$H$2:$H$8421,Transaction!$C$2:$C$8421,">="&B26,Transaction!$C$2:$C$8421,"<"&EDATE(B26,1)) -> 2151060 | D26: =COUNTIFS(Transaction!$C$2:$C$8421,">="&B26,Transaction!$C$2:$C$8421,"<"&EDATE(B26,1)) -> 961 | E26: =C26/C25-1 -> 0.050565414
A27: May 2026 | B27: 46143 | C27: =SUMIFS(Transaction!$H$2:$H$8421,Transaction!$C$2:$C$8421,">="&B27,Transaction!$C$2:$C$8421,"<"&EDATE(B27,1)) -> 2300988 | D27: =COUNTIFS(Transaction!$C$2:$C$8421,">="&B27,Transaction!$C$2:$C$8421,"<"&EDATE(B27,1)) -> 1100 | E27: =C27/C26-1 -> 0.06969959
A28: Jun 2026 | B28: 46174 | C28: =SUMIFS(Transaction!$H$2:$H$8421,Transaction!$C$2:$C$8421,">="&B28,Transaction!$C$2:$C$8421,"<"&EDATE(B28,1)) -> 2504338 | D28: =COUNTIFS(Transaction!$C$2:$C$8421,">="&B28,Transaction!$C$2:$C$8421,"<"&EDATE(B28,1)) -> 1293 | E28: =C28/C27-1 -> 0.088375081
A29: Jul 2026 | B29: 46204 | C29: =SUMIFS(Transaction!$H$2:$H$8421,Transaction!$C$2:$C$8421,">="&B29,Transaction!$C$2:$C$8421,"<"&EDATE(B29,1)) -> 2752879 | D29: =COUNTIFS(Transaction!$C$2:$C$8421,">="&B29,Transaction!$C$2:$C$8421,"<"&EDATE(B29,1)) -> 1199 | E29: =C29/C28-1 -> 0.099244191
A30: Aug 2026 | B30: 46235 | C30: =SUMIFS(Transaction!$H$2:$H$8421,Transaction!$C$2:$C$8421,">="&B30,Transaction!$C$2:$C$8421,"<"&EDATE(B30,1)) -> 3299909 | D30: =COUNTIFS(Transaction!$C$2:$C$8421,">="&B30,Transaction!$C$2:$C$8421,"<"&EDATE(B30,1)) -> 1330 | E30: =C30/C29-1 -> 0.19871197
A31: Total | C31: =SUM(C23:C30) -> 18608200 | D31: =SUM(D23:D30) -> 8420
A33: RFM Segments
A34: Segment | B34: Customers | C34: Share | D34: PPT Target | E34: Match | F34: Avg Recency (days) | G34: Avg Frequency | H34: Avg Monetary (₹)
A35: Champions | B35: =COUNTIF(Customer!$O$2:$O$2501,A35) -> 450 | C35: =B35/$B$6 -> 0.18 | D35: 0.18 | E35: =IF(ROUND(C35,2)=D35,"✓","✗") -> ✓ | F35: =AVERAGEIF(Customer!$O$2:$O$2501,A35,Customer!$M$2:$M$2501) -> 12.206667 | G35: =AVERAGEIF(Customer!$O$2:$O$2501,A35,Customer!$K$2:$K$2501) -> 9.3333333 | H35: =AVERAGEIF(Customer!$O$2:$O$2501,A35,Customer!$L$2:$L$2501) -> 20563.107
A36: Loyal Customers | B36: =COUNTIF(Customer!$O$2:$O$2501,A36) -> 600 | C36: =B36/$B$6 -> 0.24 | D36: 0.24 | E36: =IF(ROUND(C36,2)=D36,"✓","✗") -> ✓ | F36: =AVERAGEIF(Customer!$O$2:$O$2501,A36,Customer!$M$2:$M$2501) -> 50.391667 | G36: =AVERAGEIF(Customer!$O$2:$O$2501,A36,Customer!$K$2:$K$2501) -> 4.6166667 | H36: =AVERAGEIF(Customer!$O$2:$O$2501,A36,Customer!$L$2:$L$2501) -> 10284.552
A37: Potential Loyalists | B37: =COUNTIF(Customer!$O$2:$O$2501,A37) -> 675 | C37: =B37/$B$6 -> 0.27 | D37: 0.27 | E37: =IF(ROUND(C37,2)=D37,"✓","✗") -> ✓ | F37: =AVERAGEIF(Customer!$O$2:$O$2501,A37,Customer!$M$2:$M$2501) -> 45.004444 | G37: =AVERAGEIF(Customer!$O$2:$O$2501,A37,Customer!$K$2:$K$2501) -> 1 | H37: =AVERAGEIF(Customer!$O$2:$O$2501,A37,Customer!$L$2:$L$2501) -> 2139.2267
A38: At Risk | B38: =COUNTIF(Customer!$O$2:$O$2501,A38) -> 425 | C38: =B38/$B$6 -> 0.17 | D38: 0.17 | E38: =IF(ROUND(C38,2)=D38,"✓","✗") -> ✓ | F38: =AVERAGEIF(Customer!$O$2:$O$2501,A38,Customer!$M$2:$M$2501) -> 122.54353 | G38: =AVERAGEIF(Customer!$O$2:$O$2501,A38,Customer!$K$2:$K$2501) -> 1 | H38: =AVERAGEIF(Customer!$O$2:$O$2501,A38,Customer!$L$2:$L$2501) -> 1952.6612
A39: Hibernating | B39: =COUNTIF(Customer!$O$2:$O$2501,A39) -> 350 | C39: =B39/$B$6 -> 0.14 | D39: 0.14 | E39: =IF(ROUND(C39,2)=D39,"✓","✗") -> ✓ | F39: =AVERAGEIF(Customer!$O$2:$O$2501,A39,Customer!$M$2:$M$2501) -> 196.80857 | G39: =AVERAGEIF(Customer!$O$2:$O$2501,A39,Customer!$K$2:$K$2501) -> 1 | H39: =AVERAGEIF(Customer!$O$2:$O$2501,A39,Customer!$L$2:$L$2501) -> 2600.6057
A40: Total | B40: =SUM(B35:B39) -> 2500 | C40: =SUM(C35:C39) -> 1 | D40: =SUM(D35:D39) -> 1
A42: Notes & assumptions
A43: • Synthetic data generated to reconcile with the deck (blue cells = targets taken from the deck; yellow = editable snapshot date).
A44: • Each Transaction row is one order containing one product line (8,420 orders = 8,420 rows). Order Value = Quantity × Unit Price.
A45: • Unit Price is the price paid; it can sit 0–10% below the Product sheet List Price (promotions), so category revenue reconciles exactly.
...

Sheet Customer
A1: Customer ID | B1: Customer Name | C1: Gender | D1: Age | E1: City | F1: State | G1: Signup Date | H1: Acquisition Channel | I1: First Order Date | J1: Last Order Date | K1: Frequency (Orders) | L1: Monetary (₹) | M1: Recency (Days) | N1: Repeat Customer | O1: RFM Segment
A2: C0001 | B2: Aarav Naidu | C2: Male | D2: 32 | E2: Mumbai | F2: Maharashtra | G2: 46128 | H2: Organic Search | I2: =_xlfn.MINIFS(Transaction!$C$2:$C$8421,Transaction!$B$2:$B$8421,A2) -> 46131 | J2: =_xlfn.MAXIFS(Transaction!$C$2:$C$8421,Transaction!$B$2:$B$8421,A2) -> 46131 | K2: =COUNTIF(Transaction!$B$2:$B$8421,A2) -> 1 | L2: =SUMIF(Transaction!$B$2:$B$8421,A2,Transaction!$H$2:$H$8421) -> 2820 | M2: =Summary!$B$3-J2 -> 135 | N2: =IF(K2>1,"Yes","No") -> No | O2: At Risk
A3: C0002 | B3: Manish Shetty | C3: Male | D3: 30 | E3: Bengaluru | F3: Karnataka | G3: 46203 | H3: Organic Search | I3: =_xlfn.MINIFS(Transaction!$C$2:$C$8421,Transaction!$B$2:$B$8421,A3) -> 46219 | J3: =_xlfn.MAXIFS(Transaction!$C$2:$C$8421,Transaction!$B$2:$B$8421,A3) -> 46219 | K3: =COUNTIF(Transaction!$B$2:$B$8421,A3) -> 1 | L3: =SUMIF(Transaction!$B$2:$B$8421,A3,Transaction!$H$2:$H$8421) -> 54999 | M3: =Summary!$B$3-J3 -> 47 | N3: =IF(K3>1,"Yes","No") -> No | O3: Loyal Customers
A4: C0003 | B4: Komal Tiwari | C4: Female | D4: 37 | E4: Chennai | F4: Tamil Nadu | G4: 46096 | H4: Marketplace | I4: =_xlfn.MINIFS(Transaction!$C$2:$C$8421,Transaction!$B$2:$B$8421,A4) -> 46131 | J4: =_xlfn.MAXIFS(Transaction!$C$2:$C$8421,Transaction!$B$2:$B$8421,A4) -> 46131 | K4: =COUNTIF(Transaction!$B$2:$B$8421,A4) -> 1 | L4: =SUMIF(Transaction!$B$2:$B$8421,A4,Transaction!$H$2:$H$8421) -> 782 | M4: =Summary!$B$3-J4 -> 135 | N4: =IF(K4>1,"Yes","No") -> No | O4: At Risk
A5: C0004 | B5: Rajesh Joshi | C5: Male | D5: 30 | E5: Pune | F5: Maharashtra | G5: 46193 | H5: Direct | I5: =_xlfn.MINIFS(Transaction!$C$2:$C$8421,Transaction!$B$2:$B$8421,A5) -> 46193 | J5: =_xlfn.MAXIFS(Transaction!$C$2:$C$8421,Transaction!$B$2:$B$8421,A5) -> 46193 | K5: =COUNTIF(Transaction!$B$2:$B$8421,A5) -> 1 | L5: =SUMIF(Transaction!$B$2:$B$8421,A5,Transaction!$H$2:$H$8421) -> 27999 | M5: =Summary!$B$3-J5 -> 73 | N5: =IF(K5>1,"Yes","No") -> No | O5: Loyal Customers
A6: C0005 | B6: Naman Reddy | C6: Male | D6: 25 | E6: Delhi | F6: Delhi | G6: 46152 | H6: Marketplace | I6: =_xlfn.MINIFS(Transaction!$C$2:$C$8421,Transaction!$B$2:$B$8421,A6) -> 46190 | J6: =_xlfn.MAXIFS(Transaction!$C$2:$C$8421,Transaction!$B$2:$B$8421,A6) -> 46190 | K6: =COUNTIF(Transaction!$B$2:$B$8421,A6) -> 1 | L6: =SUMIF(Transaction!$B$2:$B$8421,A6,Transaction!$H$2:$H$8421) -> 7335 | M6: =Summary!$B$3-J6 -> 76 | N6: =IF(K6>1,"Yes","No") -> No | O6: Potential Loyalists
A7: C0006 | B7: Hema Mukherjee | C7: Female | D7: 40 | E7: Indore | F7: Madhya Pradesh | G7: 46127 | H7: Direct | I7: =_xlfn.MINIFS(Transaction!$C$2:$C$8421,Transaction!$B$2:$B$8421,A7) -> 46209 | J7: =_xlfn.MAXIFS(Transaction!$C$2:$C$8421,Transaction!$B$2:$B$8421,A7) -> 46209 | K7: =COUNTIF(Transaction!$B$2:$B$8421,A7) -> 1 | L7: =SUMIF(Transaction!$B$2:$B$8421,A7,Transaction!$H$2:$H$8421) -> 19999 | M7: =Summary!$B$3-J7 -> 57 | N7: =IF(K7>1,"Yes","No") -> No | O7: Loyal Customers
A8: C0007 | B8: Uma Singh | C8: Female | D8: 47 | E8: Bengaluru | F8: Karnataka | G8: 46192 | H8: Referral | I8: =_xlfn.MINIFS(Transaction!$C$2:$C$8421,Transaction!$B$2:$B$8421,A8) -> 46228 | J8: =_xlfn.MAXIFS(Transaction!$C$2:$C$8421,Transaction!$B$2:$B$8421,A8) -> 46228 | K8: =COUNTIF(Transaction!$B$2:$B$8421,A8) -> 1 | L8: =SUMIF(Transaction!$B$2:$B$8421,A8,Transaction!$H$2:$H$8421) -> 1277 | M8: =Summary!$B$3-J8 -> 38 | N8: =IF(K8>1,"Yes","No") -> No | O8: Potential Loyalists
A9: C0008 | B9: Tanvi Kulkarni | C9: Female | D9: 36 | E9: Ahmedabad | F9: Gujarat | G9: 46204 | H9: Organic Search | I9: =_xlfn.MINIFS(Transaction!$C$2:$C$8421,Transaction!$B$2:$B$8421,A9) -> 46238 | J9: =_xlfn.MAXIFS(Transaction!$C$2:$C$8421,Transaction!$B$2:$B$8421,A9) -> 46238 | K9: =COUNTIF(Transaction!$B$2:$B$8421,A9) -> 1 | L9: =SUMIF(Transaction!$B$2:$B$8421,A9,Transaction!$H$2:$H$8421) -> 9686 | M9: =Summary!$B$3-J9 -> 28 | N9: =IF(K9>1,"Yes","No") -> No | O9: Potential Loyalists
A10: C0009 | B10: Swati Chauhan | C10: Female | D10: 29 | E10: Delhi | F10: Delhi | G10: 46201 | H10: Referral | I10: =_xlfn.MINIFS(Transaction!$C$2:$C$8421,Transaction!$B$2:$B$8421,A10) -> 46210 | J10: =_xlfn.MAXIFS(Transaction!$C$2:$C$8421,Transaction!$B$2:$B$8421,A10) -> 46210 | K10: =COUNTIF(Transaction!$B$2:$B$8421,A10) -> 1 | L10: =SUMIF(Transaction!$B$2:$B$8421,A10,Transaction!$H$2:$H$8421) -> 1179 | M10: =Summary!$B$3-J10 -> 56 | N10: =IF(K10>1,"Yes","No") -> No | O10: Potential Loyalists
A11: C0010 | B11: Sunita Mukherjee | C11: Female | D11: 28 | E11: Delhi | F11: Delhi | G11: 46121 | H11: Direct | I11: =_xlfn.MINIFS(Transaction!$C$2:$C$8421,Transaction!$B$2:$B$8421,A11) -> 46207 | J11: =_xlfn.MAXIFS(Transaction!$C$2:$C$8421,Transaction!$B$2:$B$8421,A11) -> 46207 | K11: =COUNTIF(Transaction!$B$2:$B$8421,A11) -> 1 | L11: =SUMIF(Transaction!$B$2:$B$8421,A11,Transaction!$H$2:$H$8421) -> 3132 | M11: =Summary!$B$3-J11 -> 59 | N11: =IF(K11>1,"Yes","No") -> No | O11: Potential Loyalists
A12: C0011 | B12: Aishwarya Gupta | C12: Female | D12: 33 | E12: Bengaluru | F12: Karnataka | G12: 46220 | H12: Marketplace | I12: =_xlfn.MINIFS(Transaction!$C$2:$C$8421,Transaction!$B$2:$B$8421,A12) -> 46262 | J12: =_xlfn.MAXIFS(Transaction!$C$2:$C$8421,Transaction!$B$2:$B$8421,A12) -> 46262 | K12: =COUNTIF(Transaction!$B$2:$B$8421,A12) -> 1 | L12: =SUMIF(Transaction!$B$2:$B$8421,A12,Transaction!$H$2:$H$8421) -> 3128 | M12: =Summary!$B$3-J12 -> 4 | N12: =IF(K12>1,"Yes","No") -> No | O12: Potential Loyalists
A13: C0012 | B13: Pankaj Ahmed | C13: Male | D13: 38 | E13: Delhi | F13: Delhi | G13: 46176 | H13: Paid Social | I13: =_xlfn.MINIFS(Transaction!$C$2:$C$8421,Transaction!$B$2:$B$8421,A13) -> 46199 | J13: =_xlfn.MAXIFS(Transaction!$C$2:$C$8421,Transaction!$B$2:$B$8421,A13) -> 46199 | K13: =COUNTIF(Transaction!$B$2:$B$8421,A13) -> 1 | L13: =SUMIF(Transaction!$B$2:$B$8421,A13,Transaction!$H$2:$H$8421) -> 27999 | M13: =Summary!$B$3-J13 -> 67 | N13: =IF(K13>1,"Yes","No") -> No | O13: Loyal Customers
... A2501: C2500 | B2501: Rajesh Bansal | C2501: Male | D2501: 31 | E2501: Jaipur | F2501: Rajasthan | G2501: 46009 | H2501: Referral | I2501: =_xlfn.MINIFS(Transaction!$C$2:$C$8421,Transaction!$B$2:$B$8421,A2501) -> 46090 | J2501: =_xlfn.MAXIFS(Transaction!$C$2:$C$8421,Transaction!$B$2:$B$8421,A2501) -> 46090 | K2501: =COUNTIF(Transaction!$B$2:$B$8421,A2501) -> 1 | L2501: =SUMIF(Transaction!$B$2:$B$8421,A2501,Transaction!$H$2:$H$8421) -> 2140 | M2501: =Summary!$B$3-J2501 -> 176 | N2501: =IF(K2501>1,"Yes","No") -> No | O2501: Hibernating

Sheet Transaction
A1: Order ID | B1: Customer ID | C1: Order Date | D1: Product ID | E1: Category | F1: Quantity | G1: Unit Price (₹) | H1: Order Value (₹) | I1: Payment Method
A2: ORD-100001 | B2: C1523 | C2: 46023 | D2: P051 | E2: Fashion | F2: 1 | G2: 977 | H2: =F2*G2 -> 977 | I2: UPI
A3: ORD-100002 | B3: C0950 | C3: 46023 | D3: P039 | E3: Home | F3: 2 | G3: 3095 | H3: =F3*G3 -> 6190 | I3: Cash on Delivery
A4: ORD-100003 | B4: C1663 | C4: 46023 | D4: P023 | E4: Home | F4: 2 | G4: 839 | H4: =F4*G4 -> 1678 | I4: UPI
A5: ORD-100004 | B5: C1426 | C5: 46023 | D5: P027 | E5: Home | F5: 1 | G5: 589 | H5: =F5*G5 -> 589 | I5: Debit Card
A6: ORD-100005 | B6: C1478 | C6: 46023 | D6: P077 | E6: Grocery | F6: 1 | G6: 325 | H6: =F6*G6 -> 325 | I6: Net Banking
A7: ORD-100006 | B7: C0620 | C7: 46023 | D7: P079 | E7: Grocery | F7: 4 | G7: 441 | H7: =F7*G7 -> 1764 | I7: Cash on Delivery
A8: ORD-100007 | B8: C1921 | C8: 46023 | D8: P030 | E8: Home | F8: 1 | G8: 1768 | H8: =F8*G8 -> 1768 | I8: UPI
A9: ORD-100008 | B9: C1452 | C9: 46023 | D9: P065 | E9: Grocery | F9: 4 | G9: 265 | H9: =F9*G9 -> 1060 | I9: UPI
A10: ORD-100009 | B10: C1007 | C10: 46023 | D10: P006 | E10: Electronics | F10: 1 | G10: 1835 | H10: =F10*G10 -> 1835 | I10: Cash on Delivery
A11: ORD-100010 | B11: C0211 | C11: 46023 | D11: P038 | E11: Home | F11: 1 | G11: 1061 | H11: =F11*G11 -> 1061 | I11: UPI
A12: ORD-100011 | B12: C0953 | C12: 46023 | D12: P029 | E12: Home | F12: 1 | G12: 1277 | H12: =F12*G12 -> 1277 | I12: Debit Card
A13: ORD-100012 | B13: C0683 | C13: 46023 | D13: P087 | E13: Beauty | F13: 1 | G13: 661 | H13: =F13*G13 -> 661 | I13: Credit Card
... A8421: ORD-108420 | B8421: C1933 | C8421: 46265 | D8421: P069 | E8421: Grocery | F8421: 3 | G8421: 165 | H8421: =F8421*G8421 -> 495 | I8421: UPI

Sheet Product
A1: Product ID | B1: Product Name | C1: Category | D1: Sub-Category | E1: Brand | F1: List Price (₹)
A2: P001 | B2: boAt Airdopes 141 TWS Earbuds | C2: Electronics | D2: Audio | E2: boAt | F2: 1499
A3: P002 | B3: JBL Tune 230NC TWS Earbuds | C3: Electronics | D3: Audio | E3: JBL | F3: 4999
A4: P003 | B4: Sony WH-CH520 Wireless Headphones | C4: Electronics | D4: Audio | E4: Sony | F4: 3999
A5: P004 | B5: Noise ColorFit Pulse 3 Smartwatch | C5: Electronics | D5: Wearables | E5: Noise | F5: 2499
A6: P005 | B6: Fire-Boltt Ninja Call Pro Smartwatch | C6: Electronics | D6: Wearables | E6: Fire-Boltt | F6: 1999
A7: P006 | B7: Redmi Buds 5 Earbuds | C7: Electronics | D7: Audio | E7: Redmi | F7: 1799
A8: P007 | B8: Mi 20000mAh Power Bank | C8: Electronics | D8: Mobile Accessories | E8: Mi | F8: 1999
A9: P008 | B9: Anker 65W GaN Wall Charger | C9: Electronics | D9: Mobile Accessories | E9: Anker | F9: 3299
A10: P009 | B10: Samsung 25W USB-C Charger | C10: Electronics | D10: Mobile Accessories | E10: Samsung | F10: 1299
A11: P010 | B11: Logitech M331 Silent Wireless Mouse | C11: Electronics | D11: Computer Accessories | E11: Logitech | F11: 1099
A12: P011 | B12: HP K300 Backlit Gaming Keyboard | C12: Electronics | D12: Computer Accessories | E12: HP | F12: 1599
A13: P012 | B13: SanDisk Ultra 128GB Pen Drive | C13: Electronics | D13: Computer Accessories | E13: SanDisk | F13: 799
... A101: P100 | B101: Plum Green Tea Face Mask | C101: Beauty | D101: Skincare | E101: Plum | F101: 425
